<?xml version="1.0" encoding="utf-8"?>
<!-- This URDF was automatically created by SolidWorks to URDF Exporter! Originally created by Stephen Brawner (brawner@gmail.com) 
     Commit Version: 1.6.0-1-g15f4949  Build Version: 1.6.7594.29634
     For more information, please see http://wiki.ros.org/sw_urdf_exporter -->
<robot
  name="finally">
  <link
    name="base_link">
    <inertial>
      <origin
        xyz="0.0035597 0.018488 0.3"
        rpy="0 0 0" />
      <mass
        value="2.2842" />
      <inertia
        ixx="0.0066326"
        ixy="-2.2494E-19"
        ixz="1.7412E-19"
        iyy="0.0152"
        iyz="2.5455E-19"
        izz="0.020881" />
    </inertial>
    <visual>
      <origin
        xyz="0 0 0"
        rpy="0 0 0" />
      <geometry>
        <mesh
          filename="package://finally/meshes/base_link.STL" />
      </geometry>
      <material
        name="">
        <color
          rgba="0.79216 0.81961 0.93333 1" />
      </material>
    </visual>
    <collision>
      <origin
        xyz="0 0 0"
        rpy="0 0 0" />
      <geometry>
        <mesh
          filename="package://finally/meshes/base_link.STL" />
      </geometry>
    </collision>
  </link>
  <link
    name="link1">
    <inertial>
      <origin
        xyz="3.747E-16 0.12154 -0.42942"
        rpy="0 0 0" />
      <mass
        value="10.102" />
      <inertia
        ixx="0.85793"
        ixy="7.5922E-18"
        ixz="-9.0262E-17"
        iyy="0.85542"
        iyz="0.0023873"
        izz="0.019235" />
    </inertial>
    <visual>
      <origin
        xyz="0 0 0"
        rpy="0 0 0" />
      <geometry>
        <mesh
          filename="package://finally/meshes/link1.STL" />
      </geometry>
      <material
        name="">
        <color
          rgba="0.79216 0.81961 0.93333 1" />
      </material>
    </visual>
    <collision>
      <origin
        xyz="0 0 0"
        rpy="0 0 0" />
      <geometry>
        <mesh
          filename="package://finally/meshes/link1.STL" />
      </geometry>
    </collision>
  </link>
  <joint
    name="jt1"
    type="continuous">
    <origin
      xyz="0.0035597 -0.1029 -0.024327"
      rpy="-3.1416 -0.0030158 0" />
    <parent
      link="base_link" />
    <child
      link="link1" />
    <axis
      xyz="0 1 0" />
  </joint>
  <link
    name="link2">
    <inertial>
      <origin
        xyz="1.5959E-15 -0.16827 0.44411"
        rpy="0 0 0" />
      <mass
        value="10.405" />
      <inertia
        ixx="0.9299"
        ixy="1.1501E-16"
        ixz="-3.5148E-15"
        iyy="0.92508"
        iyz="0.01778"
        izz="0.021691" />
    </inertial>
    <visual>
      <origin
        xyz="0 0 0"
        rpy="0 0 0" />
      <geometry>
        <mesh
          filename="package://finally/meshes/link2.STL" />
      </geometry>
      <material
        name="">
        <color
          rgba="0.79216 0.81961 0.93333 1" />
      </material>
    </visual>
    <collision>
      <origin
        xyz="0 0 0"
        rpy="0 0 0" />
      <geometry>
        <mesh
          filename="package://finally/meshes/link2.STL" />
      </geometry>
    </collision>
  </link>
  <joint
    name="jt2"
    type="continuous">
    <origin
      xyz="0 0.049977 -0.91453"
      rpy="3.1416 0.0053869 0" />
    <parent
      link="link1" />
    <child
      link="link2" />
    <axis
      xyz="0 1 0" />
  </joint>
</robot>